<?xml version="1.0" encoding="UTF-8"?>
<!-- Generated by org.testng.reporters.JUnitReportReporter -->
<testsuite hostname="lin-nuc" name="com.epiphan.qa.tests.Test2" tests="2" failures="0" timestamp="5 May 2015 19:45:53 GMT" time="0.022" errors="1">
  <testcase name="lt" time="0.021" classname="com.epiphan.qa.tests.Test2"/>
  <testcase name="lt" time="0.001" classname="com.epiphan.qa.tests.Test2">
    <error type="java.lang.AssertionError" message="expected [1] but found [3]">
      <![CDATA[java.lang.AssertionError: expected [1] but found [3]
	at org.testng.Assert.fail(Assert.java:94)
	at org.testng.Assert.failNotEquals(Assert.java:494)
	at org.testng.Assert.assertEquals(Assert.java:123)
	at org.testng.Assert.assertEquals(Assert.java:370)
	at org.testng.Assert.assertEquals(Assert.java:380)
	at com.epiphan.qa.tests.Test2.lt(Test2.java:15)
	at sun.reflect.NativeMethodAccessorImpl.invoke0(Native Method)
	at sun.reflect.NativeMethodAccessorImpl.invoke(NativeMethodAccessorImpl.java:57)
	at sun.reflect.DelegatingMethodAccessorImpl.invoke(DelegatingMethodAccessorImpl.java:43)
	at java.lang.reflect.Method.invoke(Method.java:606)
	at org.testng.internal.MethodInvocationHelper.invokeMethod(MethodInvocationHelper.java:85)
	at org.testng.internal.Invoker.invokeMethod(Invoker.java:696)
	at org.testng.internal.Invoker.invokeTestMethod(Invoker.java:882)
	at org.testng.internal.Invoker.invokeTestMethods(Invoker.java:1189)
	at org.testng.internal.TestMethodWorker.invokeTestMethods(TestMethodWorker.java:124)
	at org.testng.internal.TestMethodWorker.run(TestMethodWorker.java:108)
	at java.util.concurrent.ThreadPoolExecutor.runWorker(ThreadPoolExecutor.java:1145)
	at java.util.concurrent.ThreadPoolExecutor$Worker.run(ThreadPoolExecutor.java:615)
	at java.lang.Thread.run(Thread.java:745)
]]>
    </error>
  </testcase> <!-- lt -->
</testsuite> <!-- com.epiphan.qa.tests.Test2 -->
